<robot name="dm2">
  <!-- Base link -->
  <link name="base_link">
    <visual>
      <origin xyz="0 0 0" rpy="0 0 0" />
      <geometry>
          <box size="0.5 0.5 0.1"/>
      </geometry>
      <material name="yellow">
        <color rgba="0.8 0.8 0 1"/>
      </material>
    </visual>
  </link>

  <!-- Front Right Wheel -->
  <link name="f_r_wheel">
    <visual>
      <origin xyz="0 0 0" rpy="1.570795 0 0" />
      <geometry>
          <cylinder length="0.1" radius="0.2" />
      </geometry>
      <material name="black">
        <color rgba="0.05 0.05 0.05 1"/>
      </material>
    </visual>
  </link>

  <!-- Front Left Wheel -->
  <link name="f_l_wheel">
    <visual>
      <origin xyz="0 0 0" rpy="1.570795 0 0" />
      <geometry>
          <cylinder length="0.1" radius="0.2" />
      </geometry>
      <material name="black"/>
    </visual>
  </link>

  <!-- joint Base Link to Left Wheel -->
  <joint name="joint_f_l_wheel" type="continuous">
    <parent link="base_link"/>
    <child link="f_l_wheel"/>
    <origin xyz="0 0.30 0" rpy="0 0 0" /> 
    <axis xyz="0 1 0" rpy="0 0 0" />
  </joint>

  <!-- joint Base Link to Right Wheel -->
  <joint name="joint_f_r_wheel" type="continuous">
    <parent link="base_link"/>
    <child link="f_r_wheel"/>
    <origin xyz="0 -0.30 0" rpy="0 0 0" /> 
    <axis xyz="0 1 0" rpy="0 0 0" />
  </joint>  

  <!-- Front Arm -->
  <link name="front_chasis_arm">
    <visual>
      <origin xyz="0 0 0" rpy="0 0 0" />
      <geometry>
          <box size="0.15 0.1 0.1"/>
      </geometry>
      <material name="red">
        <color rgba="1 0 0 1"/>
      </material>
    </visual>
  </link>

  <joint name="joint_base_f_arm" type="continuous">
    <parent link="base_link"/>
    <child link="front_chasis_arm"/>
    <origin xyz="0.325 0 0" rpy="0 0 0" /> 
    <axis xyz="0 1 0" rpy="0 0 0" />
  </joint>

  <!-- articulation -->
  <link name="articulation">
    <visual>
      <origin xyz="0 0 0" rpy="0 0 0" />
      <geometry>
          <cylinder length="0.1" radius="0.05" />
      </geometry>
      <material name="green">
        <color rgba="0 1 0 1"/>
      </material>
    </visual>
  </link>

  <joint name="joint_f_arm_art" type="continuous">
    <parent link="front_chasis_arm"/>
    <child link="articulation"/>
    <origin xyz="0.1 0 0" rpy="0 0 0" /> 
    <axis xyz="0 1 0" rpy="0 0 0" />
  </joint> 

   <link name="back_chasis_arm">
    <visual>
      <origin xyz="0 0 0" rpy="0 0 0" />
      <geometry>
          <box size="0.15 0.1 0.1"/>
      </geometry>
      <material name="red">
        <color rgba="1 0 0 1"/>
      </material>
    </visual>
  </link>

  <joint name="joint_art_b_arm" type="continuous">
    <parent link="articulation"/>
    <child link="back_chasis_arm"/>
    <origin xyz="0.1 0 0" rpy="0 0 0" /> 
    <axis xyz="0 1 0" rpy="0 0 0" />
  </joint>  

  <!-- Back chasis link -->
  <link name="back_chasis_link">
    <visual>
      <origin xyz="0 0 0" rpy="0 0 0" />
      <geometry>
          <box size="0.5 0.5 0.1"/>
      </geometry>
      <material name="yellow">
        <color rgba="0.8 0.8 0 1"/>
      </material>
    </visual>
  </link>

  <joint name="joint_b_arm_b_chasis" type="continuous">
    <parent link="back_chasis_arm"/>
    <child link="back_chasis_link"/>
    <origin xyz="0.325 0 0" rpy="0 0 0" /> 
    <axis xyz="0 1 0" rpy="0 0 0" />
  </joint>  

  <!-- Back Right Wheel -->
  <link name="b_r_wheel">
    <visual>
      <origin xyz="0 0 0" rpy="1.570795 0 0" />
      <geometry>
          <cylinder length="0.1" radius="0.2" />
      </geometry>
      <material name="black"/>
    </visual>
  </link>

  <!-- Back Left Wheel -->
  <link name="b_l_wheel">
    <visual>
      <origin xyz="0 0 0" rpy="1.570795 0 0" />
      <geometry>
          <cylinder length="0.1" radius="0.2" />
      </geometry>
      <material name="black"/>
    </visual>
  </link>

  <joint name="joint_b_r_wheel" type="continuous">
    <parent link="back_chasis_link"/>
    <child link="b_r_wheel"/>
    <origin xyz="0 -0.30 0" rpy="0 0 0" /> 
    <axis xyz="0 1 0" rpy="0 0 0" />
  </joint>  

  <joint name="joint_b_l_wheel" type="continuous">
    <parent link="back_chasis_link"/>
    <child link="b_l_wheel"/>
    <origin xyz="0 0.30 0" rpy="0 0 0" /> 
    <axis xyz="0 1 0" rpy="0 0 0" />
  </joint>
</robot>