<?xml version="1.0" ?>
<!-- =================================================================================== -->
<!-- |    This document was autogenerated by xacro from dm3.xacro                      | -->
<!-- |    EDITING THIS FILE BY HAND IS NOT RECOMMENDED                                 | -->
<!-- =================================================================================== -->
<robot name="dm3" xmlns:xacro="http://www.ros.org/wiki/xacro">
  <link name="base_link">
    <visual>
      <origin rpy="0 0 0" xyz="0 0 0"/>
      <geometry>
        <box size="0.5 0.5 0.1"/>
      </geometry>
      <material name="yellow">
        <color rgba="0.8 0.8 0 1"/>
      </material>
    </visual>
    <collision>
      <origin rpy="0 0 0" xyz="0 0 0.05"/>
      <geometry>
        <box size="0.5 0.5 0.1"/>
      </geometry>
    </collision>
    <inertial>
      <origin rpy="0 0 0" xyz="0 0 1"/>
      <mass value="5"/>
      <inertia ixx="1.0" ixy="0.0" ixz="0.0" iyy="1.0" iyz="0.0" izz="1.0"/>
    </inertial>
  </link>
  <link name="back_chasis_link">
    <visual>
      <origin rpy="0 0 0" xyz="0 0 0"/>
      <geometry>
        <box size="0.5 0.5 0.1"/>
      </geometry>
      <material name="yellow">
        <color rgba="0.8 0.8 0 1"/>
      </material>
    </visual>
    <collision>
      <origin rpy="0 0 0" xyz="0 0 0.05"/>
      <geometry>
        <box size="0.5 0.5 0.1"/>
      </geometry>
    </collision>
    <inertial>
      <origin rpy="0 0 0" xyz="0 0 1"/>
      <mass value="5"/>
      <inertia ixx="1.0" ixy="0.0" ixz="0.0" iyy="1.0" iyz="0.0" izz="1.0"/>
    </inertial>
  </link>
  <link name="f_r_wheel">
    <visual>
      <origin rpy="1.570795 0 0" xyz="0 0 0"/>
      <geometry>
        <cylinder length="0.05" radius="0.12"/>
      </geometry>
      <material name="black">
        <color rgba="0.05 0.05 0.05 1"/>
      </material>
    </visual>
    <collision>
      <origin rpy="1.570795 0 0" xyz="0 0 0"/>
      <geometry>
        <cylinder length="0.05" radius="0.12"/>
      </geometry>
    </collision>
    <inertial>
      <origin rpy="0 0 0" xyz="0 0 1"/>
      <mass value="10"/>
      <inertia ixx="1.0" ixy="0.0" ixz="0.0" iyy="1.0" iyz="0.0" izz="1.0"/>
    </inertial>
  </link>
  <link name="f_l_wheel">
    <visual>
      <origin rpy="1.570795 0 0" xyz="0 0 0"/>
      <geometry>
        <cylinder length="0.05" radius="0.12"/>
      </geometry>
      <material name="black">
        <color rgba="0.05 0.05 0.05 1"/>
      </material>
    </visual>
    <collision>
      <origin rpy="1.570795 0 0" xyz="0 0 0"/>
      <geometry>
        <cylinder length="0.05" radius="0.12"/>
      </geometry>
    </collision>
    <inertial>
      <origin rpy="0 0 0" xyz="0 0 1"/>
      <mass value="10"/>
      <inertia ixx="1.0" ixy="0.0" ixz="0.0" iyy="1.0" iyz="0.0" izz="1.0"/>
    </inertial>
  </link>
  <link name="b_l_wheel">
    <visual>
      <origin rpy="1.570795 0 0" xyz="0 0 0"/>
      <geometry>
        <cylinder length="0.05" radius="0.12"/>
      </geometry>
      <material name="black">
        <color rgba="0.05 0.05 0.05 1"/>
      </material>
    </visual>
    <collision>
      <origin rpy="1.570795 0 0" xyz="0 0 0"/>
      <geometry>
        <cylinder length="0.05" radius="0.12"/>
      </geometry>
    </collision>
    <inertial>
      <origin rpy="0 0 0" xyz="0 0 1"/>
      <mass value="10"/>
      <inertia ixx="1.0" ixy="0.0" ixz="0.0" iyy="1.0" iyz="0.0" izz="1.0"/>
    </inertial>
  </link>
  <link name="b_r_wheel">
    <visual>
      <origin rpy="1.570795 0 0" xyz="0 0 0"/>
      <geometry>
        <cylinder length="0.05" radius="0.12"/>
      </geometry>
      <material name="black">
        <color rgba="0.05 0.05 0.05 1"/>
      </material>
    </visual>
    <collision>
      <origin rpy="1.570795 0 0" xyz="0 0 0"/>
      <geometry>
        <cylinder length="0.05" radius="0.12"/>
      </geometry>
    </collision>
    <inertial>
      <origin rpy="0 0 0" xyz="0 0 1"/>
      <mass value="10"/>
      <inertia ixx="1.0" ixy="0.0" ixz="0.0" iyy="1.0" iyz="0.0" izz="1.0"/>
    </inertial>
  </link>
  <link name="front_chasis_arm">
    <visual>
      <origin rpy="0 0 0" xyz="0 0 0"/>
      <geometry>
        <box size="0.15 0.1 0.1"/>
      </geometry>
      <material name="red">
        <color rgba="1 0 0 1"/>
      </material>
    </visual>
    <collision>
      <origin rpy="0 0 0" xyz="0 0 0"/>
      <geometry>
        <box size="0.15 0.1 0.1"/>
      </geometry>
    </collision>
    <inertial>
      <origin rpy="0 0 0" xyz="0 0 1"/>
      <mass value="1"/>
      <inertia ixx="1.0" ixy="0.0" ixz="0.0" iyy="1.0" iyz="0.0" izz="1.0"/>
    </inertial>
  </link>
  <link name="back_chasis_arm">
    <visual>
      <origin rpy="0 0 0" xyz="0 0 0"/>
      <geometry>
        <box size="0.15 0.1 0.1"/>
      </geometry>
      <material name="red">
        <color rgba="1 0 0 1"/>
      </material>
    </visual>
    <collision>
      <origin rpy="0 0 0" xyz="0 0 0"/>
      <geometry>
        <box size="0.15 0.1 0.1"/>
      </geometry>
    </collision>
    <inertial>
      <origin rpy="0 0 0" xyz="0 0 1"/>
      <mass value="1"/>
      <inertia ixx="1.0" ixy="0.0" ixz="0.0" iyy="1.0" iyz="0.0" izz="1.0"/>
    </inertial>
  </link>
  <link name="articulation">
    <visual>
      <origin rpy="0 0 0" xyz="0 0 0"/>
      <geometry>
        <cylinder length="0.1" radius="0.05"/>
      </geometry>
      <material name="green">
        <color rgba="0 1 0 1"/>
      </material>
    </visual>
    <inertial>
      <origin rpy="0 0 0" xyz="0 0 1"/>
      <mass value="0.01"/>
      <inertia ixx="1.0" ixy="0.0" ixz="0.0" iyy="1.0" iyz="0.0" izz="1.0"/>
    </inertial>
  </link>
  <joint name="joint_f_l_wheel" type="continuous">
    <parent link="base_link"/>
    <child link="f_l_wheel"/>
    <origin rpy="0 0 0" xyz="0 0.275 0"/>
    <axis rpy="0 0 0" xyz="0 1 0"/>
  </joint>
  <joint name="joint_f_r_wheel" type="continuous">
    <parent link="base_link"/>
    <child link="f_r_wheel"/>
    <origin rpy="0 0 0" xyz="0 -0.275 0"/>
    <axis rpy="0 0 0" xyz="0 1 0"/>
  </joint>
  <joint name="joint_b_l_wheel" type="continuous">
    <parent link="back_chasis_link"/>
    <child link="b_l_wheel"/>
    <origin rpy="0 0 0" xyz="0 0.275 0"/>
    <axis rpy="0 0 0" xyz="0 1 0"/>
  </joint>
  <joint name="joint_b_r_wheel" type="continuous">
    <parent link="back_chasis_link"/>
    <child link="b_r_wheel"/>
    <origin rpy="0 0 0" xyz="0 -0.275 0"/>
    <axis rpy="0 0 0" xyz="0 1 0"/>
  </joint>
  <joint name="joint_front_chasis_arm_articulation" type="revolute">
    <parent link="front_chasis_arm"/>
    <child link="articulation"/>
    <origin rpy="0 0 0" xyz="0.1 0 0"/>
    <axis rpy="0 0 0" xyz="0 0 1"/>
    <limit effort="100" lower="-0.7" upper="0.7" velocity="100"/>
  </joint>
  <joint name="joint_articulation_back_chasis_arm" type="fixed">
    <parent link="articulation"/>
    <child link="back_chasis_arm"/>
    <origin rpy="0 0 0" xyz="0.1 0 0"/>
    <axis rpy="0 0 0" xyz="0 0 1"/>
    <limit effort="100" lower="-0.7" upper="0.7" velocity="100"/>
  </joint>
  <joint name="joint_base_link_front_chasis_arm" type="fixed">
    <parent link="base_link"/>
    <child link="front_chasis_arm"/>
    <origin rpy="0 0 0" xyz="0.325 0 0"/>
    <axis rpy="0 0 0" xyz="0 1 0"/>
  </joint>
  <joint name="joint_back_chasis_arm_back_chasis_link" type="fixed">
    <parent link="back_chasis_arm"/>
    <child link="back_chasis_link"/>
    <origin rpy="0 0 0" xyz="0.325 0 0"/>
    <axis rpy="0 0 0" xyz="0 1 0"/>
  </joint>
</robot>

